
================================================================================
MILB PITCH-BY-PITCH DATA GAP ANALYSIS
================================================================================
Traceback (most recent call last):
  File "C:\Users\lilra\AppData\Local\Programs\Python\Python313\Lib\site-packages\sqlalchemy\dialects\postgresql\asyncpg.py", line 521, in _prepare_and_execute
    prepared_stmt, attributes = await adapt_connection._prepare(
                                ^^^^^^^^^^^^^^^^^^^^^^^^^^^^^^^^
        operation, self._invalidate_schema_cache_asof
        ^^^^^^^^^^^^^^^^^^^^^^^^^^^^^^^^^^^^^^^^^^^^^
    )
    ^
  File "C:\Users\lilra\AppData\Local\Programs\Python\Python313\Lib\site-packages\sqlalchemy\dialects\postgresql\asyncpg.py", line 768, in _prepare
    prepared_stmt = await self._connection.prepare(
                    ^^^^^^^^^^^^^^^^^^^^^^^^^^^^^^^
        operation, name=self._prepared_statement_name_func()
        ^^^^^^^^^^^^^^^^^^^^^^^^^^^^^^^^^^^^^^^^^^^^^^^^^^^^
    )
    ^
  File "C:\Users\lilra\AppData\Local\Programs\Python\Python313\Lib\site-packages\asyncpg\connection.py", line 635, in prepare
    return await self._prepare(
           ^^^^^^^^^^^^^^^^^^^^
    ...<5 lines>...
    )
    ^
  File "C:\Users\lilra\AppData\Local\Programs\Python\Python313\Lib\site-packages\asyncpg\connection.py", line 653, in _prepare
    stmt = await self._get_statement(
           ^^^^^^^^^^^^^^^^^^^^^^^^^^
    ...<5 lines>...
    )
    ^
  File "C:\Users\lilra\AppData\Local\Programs\Python\Python313\Lib\site-packages\asyncpg\connection.py", line 432, in _get_statement
    statement = await self._protocol.prepare(
                ^^^^^^^^^^^^^^^^^^^^^^^^^^^^^
    ...<5 lines>...
    )
    ^
  File "asyncpg\\protocol\\protocol.pyx", line 165, in prepare
asyncpg.exceptions.UndefinedFunctionError: operator does not exist: text = integer
HINT:  No operator matches the given name and argument types. You might need to add explicit type casts.

The above exception was the direct cause of the following exception:

Traceback (most recent call last):
  File "C:\Users\lilra\AppData\Local\Programs\Python\Python313\Lib\site-packages\sqlalchemy\engine\base.py", line 1967, in _exec_single_context
    self.dialect.do_execute(
    ~~~~~~~~~~~~~~~~~~~~~~~^
        cursor, str_statement, effective_parameters, context
        ^^^^^^^^^^^^^^^^^^^^^^^^^^^^^^^^^^^^^^^^^^^^^^^^^^^^
    )
    ^
  File "C:\Users\lilra\AppData\Local\Programs\Python\Python313\Lib\site-packages\sqlalchemy\engine\default.py", line 951, in do_execute
    cursor.execute(statement, parameters)
    ~~~~~~~~~~~~~~^^^^^^^^^^^^^^^^^^^^^^^
  File "C:\Users\lilra\AppData\Local\Programs\Python\Python313\Lib\site-packages\sqlalchemy\dialects\postgresql\asyncpg.py", line 580, in execute
    self._adapt_connection.await_(
    ~~~~~~~~~~~~~~~~~~~~~~~~~~~~~^
        self._prepare_and_execute(operation, parameters)
        ^^^^^^^^^^^^^^^^^^^^^^^^^^^^^^^^^^^^^^^^^^^^^^^^
    )
    ^
  File "C:\Users\lilra\AppData\Local\Programs\Python\Python313\Lib\site-packages\sqlalchemy\util\_concurrency_py3k.py", line 132, in await_only
    return current.parent.switch(awaitable)  # type: ignore[no-any-return,attr-defined] # noqa: E501
           ~~~~~~~~~~~~~~~~~~~~~^^^^^^^^^^^
  File "C:\Users\lilra\AppData\Local\Programs\Python\Python313\Lib\site-packages\sqlalchemy\util\_concurrency_py3k.py", line 196, in greenlet_spawn
    value = await result
            ^^^^^^^^^^^^
  File "C:\Users\lilra\AppData\Local\Programs\Python\Python313\Lib\site-packages\sqlalchemy\dialects\postgresql\asyncpg.py", line 558, in _prepare_and_execute
    self._handle_exception(error)
    ~~~~~~~~~~~~~~~~~~~~~~^^^^^^^
  File "C:\Users\lilra\AppData\Local\Programs\Python\Python313\Lib\site-packages\sqlalchemy\dialects\postgresql\asyncpg.py", line 508, in _handle_exception
    self._adapt_connection._handle_exception(error)
    ~~~~~~~~~~~~~~~~~~~~~~~~~~~~~~~~~~~~~~~~^^^^^^^
  File "C:\Users\lilra\AppData\Local\Programs\Python\Python313\Lib\site-packages\sqlalchemy\dialects\postgresql\asyncpg.py", line 792, in _handle_exception
    raise translated_error from error
sqlalchemy.dialects.postgresql.asyncpg.AsyncAdapt_asyncpg_dbapi.ProgrammingError: <class 'asyncpg.exceptions.UndefinedFunctionError'>: operator does not exist: text = integer
HINT:  No operator matches the given name and argument types. You might need to add explicit type casts.

The above exception was the direct cause of the following exception:

Traceback (most recent call last):
  File "C:\Users\lilra\myprojects\afinewinedynasty\apps\api\investigate_pitch_data_gaps.py", line 316, in <module>
    asyncio.run(main())
    ~~~~~~~~~~~^^^^^^^^
  File "C:\Users\lilra\AppData\Local\Programs\Python\Python313\Lib\asyncio\runners.py", line 195, in run
    return runner.run(main)
           ~~~~~~~~~~^^^^^^
  File "C:\Users\lilra\AppData\Local\Programs\Python\Python313\Lib\asyncio\runners.py", line 118, in run
    return self._loop.run_until_complete(task)
           ~~~~~~~~~~~~~~~~~~~~~~~~~~~~~^^^^^^
  File "C:\Users\lilra\AppData\Local\Programs\Python\Python313\Lib\asyncio\base_events.py", line 725, in run_until_complete
    return future.result()
           ~~~~~~~~~~~~~^^
  File "C:\Users\lilra\myprojects\afinewinedynasty\apps\api\investigate_pitch_data_gaps.py", line 305, in main
    await investigate_specific_prospects()
  File "C:\Users\lilra\myprojects\afinewinedynasty\apps\api\investigate_pitch_data_gaps.py", line 34, in investigate_specific_prospects
    result = await db.execute(query)
             ^^^^^^^^^^^^^^^^^^^^^^^
  File "C:\Users\lilra\AppData\Local\Programs\Python\Python313\Lib\site-packages\sqlalchemy\ext\asyncio\session.py", line 463, in execute
    result = await greenlet_spawn(
             ^^^^^^^^^^^^^^^^^^^^^
    ...<6 lines>...
    )
    ^
  File "C:\Users\lilra\AppData\Local\Programs\Python\Python313\Lib\site-packages\sqlalchemy\util\_concurrency_py3k.py", line 201, in greenlet_spawn
    result = context.throw(*sys.exc_info())
  File "C:\Users\lilra\AppData\Local\Programs\Python\Python313\Lib\site-packages\sqlalchemy\orm\session.py", line 2365, in execute
    return self._execute_internal(
           ~~~~~~~~~~~~~~~~~~~~~~^
        statement,
        ^^^^^^^^^^
    ...<4 lines>...
        _add_event=_add_event,
        ^^^^^^^^^^^^^^^^^^^^^^
    )
    ^
  File "C:\Users\lilra\AppData\Local\Programs\Python\Python313\Lib\site-packages\sqlalchemy\orm\session.py", line 2260, in _execute_internal
    result = conn.execute(
        statement, params or {}, execution_options=execution_options
    )
  File "C:\Users\lilra\AppData\Local\Programs\Python\Python313\Lib\site-packages\sqlalchemy\engine\base.py", line 1419, in execute
    return meth(
        self,
        distilled_parameters,
        execution_options or NO_OPTIONS,
    )
  File "C:\Users\lilra\AppData\Local\Programs\Python\Python313\Lib\site-packages\sqlalchemy\sql\elements.py", line 526, in _execute_on_connection
    return connection._execute_clauseelement(
           ~~~~~~~~~~~~~~~~~~~~~~~~~~~~~~~~~^
        self, distilled_params, execution_options
        ^^^^^^^^^^^^^^^^^^^^^^^^^^^^^^^^^^^^^^^^^
    )
    ^
  File "C:\Users\lilra\AppData\Local\Programs\Python\Python313\Lib\site-packages\sqlalchemy\engine\base.py", line 1641, in _execute_clauseelement
    ret = self._execute_context(
        dialect,
    ...<8 lines>...
        cache_hit=cache_hit,
    )
  File "C:\Users\lilra\AppData\Local\Programs\Python\Python313\Lib\site-packages\sqlalchemy\engine\base.py", line 1846, in _execute_context
    return self._exec_single_context(
           ~~~~~~~~~~~~~~~~~~~~~~~~~^
        dialect, context, statement, parameters
        ^^^^^^^^^^^^^^^^^^^^^^^^^^^^^^^^^^^^^^^
    )
    ^
  File "C:\Users\lilra\AppData\Local\Programs\Python\Python313\Lib\site-packages\sqlalchemy\engine\base.py", line 1986, in _exec_single_context
    self._handle_dbapi_exception(
    ~~~~~~~~~~~~~~~~~~~~~~~~~~~~^
        e, str_statement, effective_parameters, cursor, context
        ^^^^^^^^^^^^^^^^^^^^^^^^^^^^^^^^^^^^^^^^^^^^^^^^^^^^^^^
    )
    ^
  File "C:\Users\lilra\AppData\Local\Programs\Python\Python313\Lib\site-packages\sqlalchemy\engine\base.py", line 2355, in _handle_dbapi_exception
    raise sqlalchemy_exception.with_traceback(exc_info[2]) from e
  File "C:\Users\lilra\AppData\Local\Programs\Python\Python313\Lib\site-packages\sqlalchemy\engine\base.py", line 1967, in _exec_single_context
    self.dialect.do_execute(
    ~~~~~~~~~~~~~~~~~~~~~~~^
        cursor, str_statement, effective_parameters, context
        ^^^^^^^^^^^^^^^^^^^^^^^^^^^^^^^^^^^^^^^^^^^^^^^^^^^^
    )
    ^
  File "C:\Users\lilra\AppData\Local\Programs\Python\Python313\Lib\site-packages\sqlalchemy\engine\default.py", line 951, in do_execute
    cursor.execute(statement, parameters)
    ~~~~~~~~~~~~~~^^^^^^^^^^^^^^^^^^^^^^^
  File "C:\Users\lilra\AppData\Local\Programs\Python\Python313\Lib\site-packages\sqlalchemy\dialects\postgresql\asyncpg.py", line 580, in execute
    self._adapt_connection.await_(
    ~~~~~~~~~~~~~~~~~~~~~~~~~~~~~^
        self._prepare_and_execute(operation, parameters)
        ^^^^^^^^^^^^^^^^^^^^^^^^^^^^^^^^^^^^^^^^^^^^^^^^
    )
    ^
  File "C:\Users\lilra\AppData\Local\Programs\Python\Python313\Lib\site-packages\sqlalchemy\util\_concurrency_py3k.py", line 132, in await_only
    return current.parent.switch(awaitable)  # type: ignore[no-any-return,attr-defined] # noqa: E501
           ~~~~~~~~~~~~~~~~~~~~~^^^^^^^^^^^
  File "C:\Users\lilra\AppData\Local\Programs\Python\Python313\Lib\site-packages\sqlalchemy\util\_concurrency_py3k.py", line 196, in greenlet_spawn
    value = await result
            ^^^^^^^^^^^^
  File "C:\Users\lilra\AppData\Local\Programs\Python\Python313\Lib\site-packages\sqlalchemy\dialects\postgresql\asyncpg.py", line 558, in _prepare_and_execute
    self._handle_exception(error)
    ~~~~~~~~~~~~~~~~~~~~~~^^^^^^^
  File "C:\Users\lilra\AppData\Local\Programs\Python\Python313\Lib\site-packages\sqlalchemy\dialects\postgresql\asyncpg.py", line 508, in _handle_exception
    self._adapt_connection._handle_exception(error)
    ~~~~~~~~~~~~~~~~~~~~~~~~~~~~~~~~~~~~~~~~^^^^^^^
  File "C:\Users\lilra\AppData\Local\Programs\Python\Python313\Lib\site-packages\sqlalchemy\dialects\postgresql\asyncpg.py", line 792, in _handle_exception
    raise translated_error from error
sqlalchemy.exc.ProgrammingError: (sqlalchemy.dialects.postgresql.asyncpg.ProgrammingError) <class 'asyncpg.exceptions.UndefinedFunctionError'>: operator does not exist: text = integer
HINT:  No operator matches the given name and argument types. You might need to add explicit type casts.
[SQL: 
            SELECT
                p.name,
                p.mlb_player_id,
                p.position,
                p.current_level,
                p.fg_player_id,
                COUNT(DISTINCT bp.pitch_id) as batter_pitches,
                COUNT(DISTINCT bp.game_date) as batter_games,
                STRING_AGG(DISTINCT bp.level::text, ', ' ORDER BY bp.level::text) as batter_levels,
                MIN(bp.game_date) as first_batter_pitch,
                MAX(bp.game_date) as last_batter_pitch
            FROM prospects p
            LEFT JOIN milb_batter_pitches bp ON p.mlb_player_id::text = bp.mlb_batter_id
            WHERE p.name IN ('Konnor Griffin', 'Bryce Eldridge')
            GROUP BY p.name, p.mlb_player_id, p.position, p.current_level, p.fg_player_id
            ORDER BY p.name
        ]
(Background on this error at: https://sqlalche.me/e/20/f405)
